Workbook
Name SegmentaciónDeDatos_Mes1: #N/A
Name SegmentaciónDeDatos_Unidad_Organizativa: #N/A

Sheet Presupuesto Anual
A1: Unidad Organizativa | B1: Año | C1: Escenario | D1: Mes | E1: Monto
A2: Cañaverales Mexicanos | B2: 2025 | C2: Real | D2: Enero | E2: 3607199.8
A3: Cañaverales Mexicanos | B3: 2026 | C3: Plan | D3: Enero | E3: 5905925
A4: Cañaverales Mexicanos | B4: 2026 | C4: Real | D4: Enero | E4: 4160218
A5: Cañaverales Mexicanos | B5: 2025 | C5: Real | D5: Febrero | E5: 3357703
A6: Cañaverales Mexicanos | B6: 2026 | C6: Plan | D6: Febrero | E6: 5370722
A7: Cañaverales Mexicanos | B7: 2026 | C7: Real | D7: Febrero | E7: 4577412.2
A8: Cañaverales Mexicanos | B8: 2025 | C8: Real | D8: Marzo | E8: 3763070.3
A9: Cañaverales Mexicanos | B9: 2026 | C9: Plan | D9: Marzo | E9: 5789408
A10: Cañaverales Mexicanos | B10: 2026 | C10: Real | D10: Marzo | E10: 4769875.8
A11: Cañaverales Mexicanos | B11: 2025 | C11: Real | D11: Abril | E11: 3980928.5
A12: Cañaverales Mexicanos | B12: 2026 | C12: Plan | D12: Abril | E12: 5596513
A13: Cañaverales Mexicanos | B13: 2026 | C13: Real | D13: Abril
A14: Cañaverales Mexicanos | B14: 2025 | C14: Real | D14: Mayo | E14: 4523879.6
A15: Cañaverales Mexicanos | B15: 2026 | C15: Plan | D15: Mayo | E15: 3798934
A16: Cañaverales Mexicanos | B16: 2026 | C16: Real | D16: Mayo
A17: Cañaverales Mexicanos | B17: 2025 | C17: Real | D17: Junio | E17: 2745004.4
A18: Cañaverales Mexicanos | B18: 2026 | C18: Plan | D18: Junio | E18: 3159916
A19: Cañaverales Mexicanos | B19: 2026 | C19: Real | D19: Junio
A20: Cañaverales Mexicanos | B20: 2025 | C20: Real | D20: Julio | E20: 2940007
A21: Cañaverales Mexicanos | B21: 2026 | C21: Plan | D21: Julio | E21: 2945542
A22: Cañaverales Mexicanos | B22: 2026 | C22: Real | D22: Julio
A23: Cañaverales Mexicanos | B23: 2025 | C23: Real | D23: Agosto | E23: 2594544.9
A24: Cañaverales Mexicanos | B24: 2026 | C24: Plan | D24: Agosto | E24: 2905775
A25: Cañaverales Mexicanos | B25: 2026 | C25: Real | D25: Agosto
A26: Cañaverales Mexicanos | B26: 2025 | C26: Real | D26: Septiembre | E26: 2645532.6
A27: Cañaverales Mexicanos | B27: 2026 | C27: Plan | D27: Septiembre | E27: 2776535
A28: Cañaverales Mexicanos | B28: 2026 | C28: Real | D28: Septiembre
A29: Cañaverales Mexicanos | B29: 2025 | C29: Real | D29: Octubre | E29: 3195507.2
A30: Cañaverales Mexicanos | B30: 2026 | C30: Plan | D30: Octubre | E30: 2808591
A31: Cañaverales Mexicanos | B31: 2026 | C31: Real | D31: Octubre
A32: Cañaverales Mexicanos | B32: 2025 | C32: Real | D32: Noviembre | E32: 2578258.6
A33: Cañaverales Mexicanos | B33: 2026 | C33: Plan | D33: Noviembre | E33: 3007678
A34: Cañaverales Mexicanos | B34: 2026 | C34: Real | D34: Noviembre
A35: Cañaverales Mexicanos | B35: 2025 | C35: Real | D35: Diciembre | E35: 2583031.1
A36: Cañaverales Mexicanos | B36: 2026 | C36: Plan | D36: Diciembre | E36: 5781158
A37: Cañaverales Mexicanos | B37: 2026 | C37: Real | D37: Diciembre
A38: Excelencia Zona Chiapas | B38: 2026 | C38: Plan | D38: Enero | E38: 5858754.7
A39: Excelencia Zona Chiapas | B39: 2026 | C39: Real | D39: Enero | E39: 4023683.5
A40: Excelencia Zona Chiapas | B40: 2025 | C40: Real | D40: Enero | E40: 4710916.4
...

Sheet Analisis2
A1: Año | B1: 2026 | D1: Año | E1: 2026 | G1: Año | H1: 2026 | J1: Año | K1: 2026 | M1: Año | N1: 2025 | P1: Año | Q1: 2026 | S1: Año | T1: 2025
A2: Escenario | B2: Plan | D2: Escenario | E2: Real | G2: Escenario | H2: Plan | J2: Escenario | K2: Real | M2: Escenario | N2: Real | P2: Escenario | Q2: Real | S2: Escenario | T2: Real
A4: Etiquetas de fila | B4: Suma de Monto | D4: Etiquetas de fila | E4: Suma de Monto | G4: Etiquetas de fila | H4: Suma de Monto | J4: Etiquetas de fila | K4: Suma de Monto | M4: Etiquetas de fila | N4: Suma de Monto | P4: Etiquetas de fila | Q4: Suma de Monto | S4: Etiquetas de fila | T4: Suma de Monto
A5: Excelencia Zona Veracruz | B5: 2116470 | D5: Excelencia Zona Veracruz | E5: 1475048.2 | G5: Enero | H5: 1922414 | J5: Enero | K5: 1221260.1 | M5: Enero | N5: 1475128.9 | P5: Marzo | Q5: 1475048.2 | S5: Marzo | T5: 1404391.4
A6: Total general | B6: 2116470 | D6: Total general | E6: 1475048.2 | G6: Febrero | H6: 1901092 | J6: Febrero | K6: 1314436 | M6: Febrero | N6: 1282644 | P6: Total general | Q6: 1475048.2 | S6: Total general | T6: 1404391.4
G7: Marzo | H7: 2116470 | J7: Marzo | K7: 1475048.2 | M7: Marzo | N7: 1404391.4
G8: Abril | H8: 2041821 | J8: Abril | M8: Abril | N8: 1506428.7
G9: Mayo | H9: 2107918 | J9: Mayo | M9: Mayo | N9: 1796601.6
G10: Junio | H10: 1859459 | J10: Junio | M10: Junio | N10: 1350865
G11: Julio | H11: 1716089 | J11: Julio | M11: Julio | N11: 1351927.4
G12: Agosto | H12: 1677671 | J12: Agosto | M12: Agosto | N12: 1179118.5
G13: Septiembre | H13: 1420890 | J13: Septiembre | M13: Septiembre | N13: 1086631.6
G14: Octubre | H14: 1346884 | J14: Octubre | M14: Octubre | N14: 1224896.2
G15: Noviembre | H15: 1489354 | J15: Noviembre | M15: Noviembre | N15: 944428.09
G16: Diciembre | H16: 1870731 | J16: Diciembre | M16: Diciembre | N16: 922559.33
G17: Total general | H17: 21470793 | J17: Total general | K17: 4010744.3 | M17: Total general | N17: 15525621

Sheet Info
B1: Plan 2026 | C1: =GETPIVOTDATA("Monto",Analisis2!$A$4) -> 2116470
B2: Real 2026 | C2: =GETPIVOTDATA("Monto",Analisis2!$D$4) -> 1475048.2
C3: =IFERROR(((C1-C2)/C1),0) -> 0.30306204 | D3: =IF(C3=0,0,1-C3) -> 0.69693796
B4: Ahorro Absoluto 2025 | C4: =C2-C1 -> -641421.7
A5: Plan 2026 | B5: Enero | C5: =_xlfn.XLOOKUP(B5,Analisis2!G:G,Analisis2!H:H,"") -> 1922414
B6: Febrero | C6: =_xlfn.XLOOKUP(B6,Analisis2!G:G,Analisis2!H:H,"") -> 1901092
B7: Marzo | C7: =_xlfn.XLOOKUP(B7,Analisis2!G:G,Analisis2!H:H,"") -> 2116470
B8: Abril | C8: =_xlfn.XLOOKUP(B8,Analisis2!G:G,Analisis2!H:H,"") -> 2041821
B9: Mayo | C9: =_xlfn.XLOOKUP(B9,Analisis2!G:G,Analisis2!H:H,"") -> 2107918
B10: Junio | C10: =_xlfn.XLOOKUP(B10,Analisis2!G:G,Analisis2!H:H,"") -> 1859459
B11: Julio | C11: =_xlfn.XLOOKUP(B11,Analisis2!G:G,Analisis2!H:H,"") -> 1716089
B12: Agosto | C12: =_xlfn.XLOOKUP(B12,Analisis2!G:G,Analisis2!H:H,"") -> 1677671
B13: Septiembre | C13: =_xlfn.XLOOKUP(B13,Analisis2!G:G,Analisis2!H:H,"") -> 1420890
B14: Octubre | C14: =_xlfn.XLOOKUP(B14,Analisis2!G:G,Analisis2!H:H,"") -> 1346884
B15: Noviembre | C15: =_xlfn.XLOOKUP(B15,Analisis2!G:G,Analisis2!H:H,"") -> 1489354
B16: Diciembre | C16: =_xlfn.XLOOKUP(B16,Analisis2!G:G,Analisis2!H:H,"") -> 1870731
A17: Real 2026 | B17: Enero | C17: =_xlfn.XLOOKUP(B17,Analisis2!J:J,Analisis2!K:K,"") -> 1221260.1
B18: Febrero | C18: =_xlfn.XLOOKUP(B18,Analisis2!J:J,Analisis2!K:K,"") -> 1314436
B19: Marzo | C19: =_xlfn.XLOOKUP(B19,Analisis2!J:J,Analisis2!K:K,"") -> 1475048.2
B20: Abril | C20: =_xlfn.XLOOKUP(B20,Analisis2!J:J,Analisis2!K:K,"") -> 0
B21: Mayo | C21: =_xlfn.XLOOKUP(B21,Analisis2!J:J,Analisis2!K:K,"") -> 0
B22: Junio | C22: =_xlfn.XLOOKUP(B22,Analisis2!J:J,Analisis2!K:K,"") -> 0
B23: Julio | C23: =_xlfn.XLOOKUP(B23,Analisis2!J:J,Analisis2!K:K,"") -> 0
B24: Agosto | C24: =_xlfn.XLOOKUP(B24,Analisis2!J:J,Analisis2!K:K,"") -> 0
B25: Septiembre | C25: =_xlfn.XLOOKUP(B25,Analisis2!J:J,Analisis2!K:K,"") -> 0
B26: Octubre | C26: =_xlfn.XLOOKUP(B26,Analisis2!J:J,Analisis2!K:K,"") -> 0
B27: Noviembre | C27: =_xlfn.XLOOKUP(B27,Analisis2!J:J,Analisis2!K:K,"") -> 0
B28: Diciembre | C28: =_xlfn.XLOOKUP(B28,Analisis2!J:J,Analisis2!K:K,"") -> 0
A29: Ahorro/Sobre Gasto | B29: Enero | C29: =IF(C17=0,0,C17-C5) -> -701153.9
B30: Febrero | C30: =IF(C18=0,0,C18-C6) -> -586656.04
B31: Marzo | C31: =IF(C19=0,0,C19-C7) -> -641421.7
B32: Abril | C32: =IF(C20=0,0,C20-C8) -> 0
B33: Mayo | C33: =IF(C21=0,0,C21-C9) -> 0
B34: Junio | C34: =IF(C22=0,0,C22-C10) -> 0
B35: Julio | C35: =IF(C23=0,0,C23-C11) -> 0
B36: Agosto | C36: =IF(C24=0,0,C24-C12) -> 0
B37: Septiembre | C37: =IF(C25=0,0,C25-C13) -> 0
B38: Octubre | C38: =IF(C26=0,0,C26-C14) -> 0
B39: Noviembre | C39: =IF(C27=0,0,C27-C15) -> 0
B40: Diciembre | C40: =IF(C28=0,0,C28-C16) -> 0
...

Sheet DashBoard
